Workbook
Name Mes: Mes!$A$2

Sheet BASE
A1: ANIO_NATURAL_MES | B1: POSICION | C1: DESCRIPCION_POSICION | D1: AREA_FUNCIONAL | E1: SUB_AREA_FUNCIONAL | F1: FUNCION | G1: DESCRIPCION_FUNCION | H1: ID_META_4 | I1: SUBDIV_PERSONAL | J1: SOCIEDAD | K1: NOMBRE_JEFE | L1: OBJETO_DE_IMPUTACION | M1: PERSONA | N1: DESCRIPCION_PERSONA | O1: FLAG_LICENCIA | P1: NACIONALIDAD | Q1: USUARIO_DE_RED | R1: OPERACION_PIVOT | S1: OPERACION_DETALLE | T1: UO | U1: GERENCIA_JEFATURA | V1: WC_BC | W1: SEXO | X1: RANGO_ETARIO | Y1: EDAD | Z1: ANIOS_ANTIGUEDAD | AA1: GRUPO_ANTIGUEDAD | AB1: FUENTE | AC1: HC | AD1: EA | AE1: BUDGET | AF1: ENCUADRE | AG1: CLUSTER | AH1: NO_HC | AI1: CS | AJ1: OL | AK1: FECHA_ANIVERSARIO_SAP
A2: 46266 | B2: 3360828 | C2: O&M Services Director | D2: EFIS | E2: EFIS | G2: =Table1[[#This Row],[DESCRIPCION_POSICION]] -> O&M Services Director | H2: DU20916565 | I2: AR-NEUQUÉN | J2: TECPETROL S.A. | K2: Mamani Carlos Walter | L2: FPF-FN0940 | N2: Lusso Mauricio Ricardo | O2: =VLOOKUP(L2,CECOs!A:B,2,0) -> Sueldos TECPE | P2: =VLOOKUP(B:B,CECOs!G:I,3,FALSE) -> #N/A | Q2: =IF(_xlfn.XLOOKUP(L2,CECOs!A:A,CECOs!C:C,"")="",K2,_xlfn.XLOOKUP(L2,CECOs!A:A,CECOs!C:C,"")) -> Mamani Carlos Walter | R2: EFIS | S2: NQN | T2: 1005464 | U2: O&M Services | V2: WC | AB2: Headcount | AD2: SI
A3: 46266 | B3: 3417016 | C3: O&M Services Sr. Manager | D3: EFIS | E3: EFIS | G3: =Table1[[#This Row],[DESCRIPCION_POSICION]] -> O&M Services Sr. Manager | H3: DU29109359 | I3: AR-NEUQUÉN | J3: TECPETROL S.A. | K3: Lusso Mauricio Ricardo | L3: FPF-FN0940 | N3: Fabro Facundo | O3: =VLOOKUP(L3,CECOs!A:B,2,0) -> Sueldos TECPE | P3: =VLOOKUP(B:B,CECOs!G:I,3,FALSE) -> #N/A | Q3: =IF(_xlfn.XLOOKUP(L3,CECOs!A:A,CECOs!C:C,"")="",K3,_xlfn.XLOOKUP(L3,CECOs!A:A,CECOs!C:C,"")) -> Lusso Mauricio Ricardo | R3: EFIS | S3: NQN | U3: O&M Services | V3: WC | AB3: Headcount | AD3: SI
A4: 46266 | B4: 3197992 | C4: Maintenance Services Manager | D4: EFIS | E4: EFIS | G4: =Table1[[#This Row],[DESCRIPCION_POSICION]] -> Maintenance Services Manager | H4: DU28636995 | I4: AR-NEUQUÉN | J4: TECPETROL S.A. | K4: Fabro Facundo | L4: FPF-FN0940 | N4: Batallan Pablo Alejandro | O4: =VLOOKUP(L4,CECOs!A:B,2,0) -> Sueldos TECPE | P4: =VLOOKUP(B:B,CECOs!G:I,3,FALSE) -> #N/A | Q4: =IF(_xlfn.XLOOKUP(L4,CECOs!A:A,CECOs!C:C,"")="",K4,_xlfn.XLOOKUP(L4,CECOs!A:A,CECOs!C:C,"")) -> Fabro Facundo | R4: EFIS | S4: NQN | T4: 1016733 | U4: O&M Services | V4: WC | AB4: Headcount | AD4: SI
A5: 46266 | B5: 3294913 | C5: Operations Services Manager | D5: EFIS | E5: EFIS | G5: =Table1[[#This Row],[DESCRIPCION_POSICION]] -> Operations Services Manager | H5: DU33774464 | I5: AR-NEUQUÉN | J5: TECPETROL S.A. | K5: Fabro Facundo | L5: FPF-FN0940 | N5: Beloqui Leandro | O5: =VLOOKUP(L5,CECOs!A:B,2,0) -> Sueldos TECPE | P5: =VLOOKUP(B:B,CECOs!G:I,3,FALSE) -> #N/A | Q5: =IF(_xlfn.XLOOKUP(L5,CECOs!A:A,CECOs!C:C,"")="",K5,_xlfn.XLOOKUP(L5,CECOs!A:A,CECOs!C:C,"")) -> Fabro Facundo | R5: EFIS | S5: NQN | T5: 1016735 | U5: O&M Services | V5: WC | AB5: Headcount | AD5: SI
A6: 46266 | B6: 3364085 | C6: O&M Optimization Process Analyst | D6: EFIS | E6: EFIS | G6: =Table1[[#This Row],[DESCRIPCION_POSICION]] -> O&M Optimization Process Analyst | H6: DU40927304 | I6: AR-NEUQUÉN | J6: TECPETROL S.A. | K6: Lusso Mauricio Ricardo | L6: FPF-FN0940 | N6: Gili Arianna | O6: =VLOOKUP(L6,CECOs!A:B,2,0) -> Sueldos TECPE | P6: =VLOOKUP(B:B,CECOs!G:I,3,FALSE) -> #N/A | Q6: =IF(_xlfn.XLOOKUP(L6,CECOs!A:A,CECOs!C:C,"")="",K6,_xlfn.XLOOKUP(L6,CECOs!A:A,CECOs!C:C,"")) -> Lusso Mauricio Ricardo | R6: EFIS | S6: NQN | T6: 1016737 | U6: O&M Services | V6: WC | AB6: Headcount | AD6: SI
A7: 46266 | B7: 3392801 | C7: Maintenance Services Coordinator | D7: EFIS | E7: EFIS | G7: =Table1[[#This Row],[DESCRIPCION_POSICION]] -> Maintenance Services Coordinator | H7: DU28063207 | I7: AR-NEUQUÉN | J7: Energy Field Services | K7: Batallan Pablo Alejandro | L7: EFR-FN0920 | N7: Huarte Esteban | O7: =VLOOKUP(L7,CECOs!A:B,2,0) -> Facilitadores FP | P7: =VLOOKUP(B:B,CECOs!G:I,3,FALSE) -> FacilitadordeServicios | Q7: =IF(_xlfn.XLOOKUP(L7,CECOs!A:A,CECOs!C:C,"")="",K7,_xlfn.XLOOKUP(L7,CECOs!A:A,CECOs!C:C,"")) -> Batallan Pablo Alejandro | R7: EFIS | S7: NQN | T7: 1016733 | U7: O&M Services | V7: WC | AB7: Headcount | AD7: SI
A8: 46266 | B8: 3392802 | C8: Operations Services Coordinator | D8: EFIS | E8: EFIS | G8: =Table1[[#This Row],[DESCRIPCION_POSICION]] -> Operations Services Coordinator | H8: DU32090502 | I8: AR-NEUQUÉN | J8: Energy Field Services | K8: Batallan Pablo Alejandro | L8: EFR-FN0920 | N8: Cordova Daniela Emiliana | O8: =VLOOKUP(L8,CECOs!A:B,2,0) -> Facilitadores FP | P8: =VLOOKUP(B:B,CECOs!G:I,3,FALSE) -> FacilitadordeServicios | Q8: =IF(_xlfn.XLOOKUP(L8,CECOs!A:A,CECOs!C:C,"")="",K8,_xlfn.XLOOKUP(L8,CECOs!A:A,CECOs!C:C,"")) -> Batallan Pablo Alejandro | R8: EFIS | S8: NQN | T8: 1016733 | U8: O&M Services | V8: WC | AB8: Headcount | AD8: SI
A9: 46266 | B9: 3392803 | C9: Maintenance Services Coordinator | D9: EFIS | E9: EFIS | G9: =Table1[[#This Row],[DESCRIPCION_POSICION]] -> Maintenance Services Coordinator | H9: DU34666188 | I9: AR-NEUQUÉN | J9: Energy Field Services | K9: Batallan Pablo Alejandro | L9: EFR-FN0920 | N9: Altamiranda Leandro Damian | O9: =VLOOKUP(L9,CECOs!A:B,2,0) -> Facilitadores FP | P9: =VLOOKUP(B:B,CECOs!G:I,3,FALSE) -> FacilitadordeServicios | Q9: =IF(_xlfn.XLOOKUP(L9,CECOs!A:A,CECOs!C:C,"")="",K9,_xlfn.XLOOKUP(L9,CECOs!A:A,CECOs!C:C,"")) -> Batallan Pablo Alejandro | R9: EFIS | S9: NQN | T9: 1016733 | U9: O&M Services | V9: WC | AB9: Headcount | AD9: SI
A10: 46266 | B10: 3392804 | C10: Production Services Coordinator | D10: EFIS | E10: EFIS | G10: =Table1[[#This Row],[DESCRIPCION_POSICION]] -> Production Services Coordinator | H10: DU24131475 | I10: AR-NEUQUÉN | J10: Energy Field Services | K10: Lopez Rodrigo Gaston | L10: EFR-FN2007 | N10: Macias Ceferino Oscar | O10: =VLOOKUP(L10,CECOs!A:B,2,0) -> Supervisores Well Services | P10: =VLOOKUP(B:B,CECOs!G:I,3,FALSE) -> FacilitadordeServicios | Q10: =IF(_xlfn.XLOOKUP(L10,CECOs!A:A,CECOs!C:C,"")="",K10,_xlfn.XLOOKUP(L10,CECOs!A:A,CECOs!C:C,"")) -> Lopez Rodrigo Gaston | R10: EFIS | S10: NQN | T10: 1016735 | U10: O&M Services | V10: WC | AB10: Headcount | AD10: SI
A11: 46266 | B11: 3392805 | C11: Plants Services Coordinator | D11: EFIS | E11: EFIS | G11: =Table1[[#This Row],[DESCRIPCION_POSICION]] -> Plants Services Coordinator | H11: DU32195174 | I11: AR-NEUQUÉN | J11: Energy Field Services | K11: Lopez Rodrigo Gaston | L11: EFR-FN0900 | N11: Bechara Lucas Antonio | O11: =VLOOKUP(L11,CECOs!A:B,2,0) -> Facilitadores CONV | P11: =VLOOKUP(B:B,CECOs!G:I,3,FALSE) -> FacilitadordeServicios | Q11: =IF(_xlfn.XLOOKUP(L11,CECOs!A:A,CECOs!C:C,"")="",K11,_xlfn.XLOOKUP(L11,CECOs!A:A,CECOs!C:C,"")) -> Lopez Rodrigo Gaston | R11: EFIS | S11: NQN | T11: 1016735 | U11: O&M Services | V11: WC | AB11: Headcount | AD11: SI
A12: 46266 | B12: 3392806 | C12: Operations Services Coordinator | D12: EFIS | E12: EFIS | G12: =Table1[[#This Row],[DESCRIPCION_POSICION]] -> Operations Services Coordinator | H12: DU30191811 | I12: AR-NEUQUÉN | J12: Energy Field Services | K12: Lopez Rodrigo Gaston | L12: EFR-FN0920 | N12: Casal Gustavo Daniel | O12: =VLOOKUP(L12,CECOs!A:B,2,0) -> Facilitadores FP | P12: =VLOOKUP(B:B,CECOs!G:I,3,FALSE) -> FacilitadordeServicios | Q12: =IF(_xlfn.XLOOKUP(L12,CECOs!A:A,CECOs!C:C,"")="",K12,_xlfn.XLOOKUP(L12,CECOs!A:A,CECOs!C:C,"")) -> Lopez Rodrigo Gaston | R12: EFIS | S12: NQN | T12: 1016735 | U12: O&M Services | V12: WC | AB12: Headcount | AD12: SI
A13: 46266 | B13: 3392808 | C13: Technical Training Specialist | D13: EFIS | E13: EFIS | G13: =Table1[[#This Row],[DESCRIPCION_POSICION]] -> Technical Training Specialist | H13: DU36800803 | I13: AR-NEUQUÉN | J13: Energy Field Services | K13: Lopez Rodrigo Gaston | L13: EFR-FN0920 | N13: Poblete Matias Ezequiel | O13: =VLOOKUP(L13,CECOs!A:B,2,0) -> Facilitadores FP | P13: =VLOOKUP(B:B,CECOs!G:I,3,FALSE) -> FacilitadordeServicios | Q13: =IF(_xlfn.XLOOKUP(L13,CECOs!A:A,CECOs!C:C,"")="",K13,_xlfn.XLOOKUP(L13,CECOs!A:A,CECOs!C:C,"")) -> Lopez Rodrigo Gaston | R13: EFIS | S13: NQN | T13: 1016735 | U13: O&M Services | V13: WC | AB13: Headcount | AD13: SI
A14: 46266 | B14: 3406970 | C14: Oficial Especializado de Oficios | D14: EFIS | E14: EFIS | G14: =Table1[[#This Row],[DESCRIPCION_POSICION]] -> Oficial Especializado de Oficios | H14: DU47368614 | I14: AR-NEUQUÉN | J14: Energy Field Services | K14: Cordova Daniela Emiliana | L14: EFF-FP0921 | N14: Gonzalez Mendez Simon | O14: =VLOOKUP(L14,CECOs!A:B,2,0) -> Mtto Mecánico FP | P14: =VLOOKUP(B:B,CECOs!G:I,3,FALSE) -> Relevomantenimiento | Q14: =IF(_xlfn.XLOOKUP(L14,CECOs!A:A,CECOs!C:C,"")="",K14,_xlfn.XLOOKUP(L14,CECOs!A:A,CECOs!C:C,"")) -> CORDOVA, DANIELA / ALTAMIRANDA, LEANDRO | R14: EFIS | S14: NQN | U14: Maintenance | V14: BC | AB14: Headcount | AD14: SI
A15: 46266 | B15: 3414076 | C15: Maintenance Supervisor | D15: EFIS | E15: EFIS | G15: =Table1[[#This Row],[DESCRIPCION_POSICION]] -> Maintenance Supervisor | H15: DU40778151 | I15: AR-NEUQUÉN | J15: Energy Field Services | K15: Segura Alejandro | L15: EFF-FN1000 | N15: Gazzola Ezequiel | O15: =VLOOKUP(L15,CECOs!A:B,2,0) -> PJ TLM | P15: =VLOOKUP(B:B,CECOs!G:I,3,FALSE) -> Supervisoroperativo/Producción | Q15: =IF(_xlfn.XLOOKUP(L15,CECOs!A:A,CECOs!C:C,"")="",K15,_xlfn.XLOOKUP(L15,CECOs!A:A,CECOs!C:C,"")) -> Segura Alejandro | R15: EFIS | S15: NQN | U15: Maintenance | V15: WC | AB15: Headcount | AD15: SI
A16: 46266 | B16: 3392809 | C16: O&M Planning Analyst | D16: EFIS | E16: EFIS | G16: =Table1[[#This Row],[DESCRIPCION_POSICION]] -> O&M Planning Analyst | H16: DU41254675 | I16: AR-NEUQUÉN | J16: TECPETROL S.A. | K16: Gili Arianna | L16: FPF-FN0940 | N16: Baza Coseani Luisina | O16: =VLOOKUP(L16,CECOs!A:B,2,0) -> Sueldos TECPE | P16: =VLOOKUP(B:B,CECOs!G:I,3,FALSE) -> #N/A | Q16: =IF(_xlfn.XLOOKUP(L16,CECOs!A:A,CECOs!C:C,"")="",K16,_xlfn.XLOOKUP(L16,CECOs!A:A,CECOs!C:C,"")) -> Gili Arianna | R16: EFIS | S16: NQN | T16: 1016737 | U16: O&M Services | V16: WC | AB16: Headcount | AD16: SI
A17: 46266 | B17: 33928091 | C17: O&M Planning trainee | D17: EFIS | E17: EFIS | H17: DU46293912 | I17: AR-NEUQUÉN | J17: TECPETROL S.A. | K17: Gili Arianna | L17: FPF-FN0940 | N17: Vidic Alenka | O17: =VLOOKUP(L17,CECOs!A:B,2,0) -> Sueldos TECPE | P17: =VLOOKUP(B:B,CECOs!G:I,3,FALSE) -> #N/A | Q17: =IF(_xlfn.XLOOKUP(L17,CECOs!A:A,CECOs!C:C,"")="",K17,_xlfn.XLOOKUP(L17,CECOs!A:A,CECOs!C:C,"")) -> Gili Arianna | R17: EFIS | S17: NQN | U17: O&M Services | V17: WC
A18: 46266 | B18: 3392810 | C18: Accounts Payable Analyst | D18: EFIS | E18: EFIS | G18: =Table1[[#This Row],[DESCRIPCION_POSICION]] -> Accounts Payable Analyst | H18: DU43137970 | I18: AR-NEUQUÉN | J18: TECPETROL S.A. | K18: Romano Mariano Bruno | L18: FPF-FN0940 | N18: Sandalich Victoria | O18: =VLOOKUP(L18,CECOs!A:B,2,0) -> Sueldos TECPE | P18: =VLOOKUP(B:B,CECOs!G:I,3,FALSE) -> #N/A | Q18: =IF(_xlfn.XLOOKUP(L18,CECOs!A:A,CECOs!C:C,"")="",K18,_xlfn.XLOOKUP(L18,CECOs!A:A,CECOs!C:C,"")) -> Romano Mariano Bruno | R18: EFIS | S18: NQN | T18: 1000268 | U18: Adm. & Finance Neuquén | V18: WC | AB18: Headcount | AD18: SI
A19: 46266 | B19: 3392811 | C19: HRBP Analyst | D19: EFIS | E19: EFIS | G19: =Table1[[#This Row],[DESCRIPCION_POSICION]] -> HRBP Analyst | H19: DU39076574 | I19: AR-NEUQUÉN | J19: Energy Field Services | K19: Corbalan Federico Martin | L19: EFR-FN0941 | N19: Barrera Anahi Malen | O19: =VLOOKUP(L19,CECOs!A:B,2,0) -> Indirectos PRR | P19: =VLOOKUP(B:B,CECOs!G:I,3,FALSE) -> Personalnooperativo | Q19: =IF(_xlfn.XLOOKUP(L19,CECOs!A:A,CECOs!C:C,"")="",K19,_xlfn.XLOOKUP(L19,CECOs!A:A,CECOs!C:C,"")) -> Corbalan Federico Martin | R19: EFIS | S19: NQN | T19: 1005464 | U19: Human Resources | V19: WC | AB19: Headcount | AD19: SI
A20: 46266 | B20: 3392812 | C20: HRBP Sr. Analyst | D20: EFIS | E20: EFIS | G20: =Table1[[#This Row],[DESCRIPCION_POSICION]] -> HRBP Sr. Analyst | H20: DU36801186 | I20: AR-NEUQUÉN | J20: Energy Field Services | K20: Corbalan Federico Martin | L20: EFR-FN0941 | N20: Tarifeño Ernesto Eduardo | O20: =VLOOKUP(L20,CECOs!A:B,2,0) -> Indirectos PRR | P20: =VLOOKUP(B:B,CECOs!G:I,3,FALSE) -> Personalnooperativo | Q20: =IF(_xlfn.XLOOKUP(L20,CECOs!A:A,CECOs!C:C,"")="",K20,_xlfn.XLOOKUP(L20,CECOs!A:A,CECOs!C:C,"")) -> Corbalan Federico Martin | R20: EFIS | S20: NQN | T20: 1005464 | U20: Human Resources | V20: WC | AB20: Headcount | AD20: SI
A21: 46266 | B21: 3423705 | C21: HRBP Sr. Analyst | D21: EFIS | E21: EFIS | G21: =Table1[[#This Row],[DESCRIPCION_POSICION]] -> HRBP Sr. Analyst | H21: DU36257444 | I21: AR-NEUQUÉN | J21: Energy Field Services | K21: Corbalan Federico Martin | L21: EFR-FN0941 | N21: Soria Agustin Gabriel | O21: =VLOOKUP(L21,CECOs!A:B,2,0) -> Indirectos PRR | P21: =VLOOKUP(B:B,CECOs!G:I,3,FALSE) -> Personalnooperativo | Q21: =IF(_xlfn.XLOOKUP(L21,CECOs!A:A,CECOs!C:C,"")="",K21,_xlfn.XLOOKUP(L21,CECOs!A:A,CECOs!C:C,"")) -> Corbalan Federico Martin | R21: EFIS | S21: NQN | T21: 1005464 | U21: Human Resources | V21: WC | AB21: Headcount | AD21: SI
A22: 46266 | B22: 3437875 | C22: HRBP Analyst | D22: EFIS | E22: EFIS | G22: =Table1[[#This Row],[DESCRIPCION_POSICION]] -> HRBP Analyst | H22: DU43084808 | I22: AR-NEUQUÉN | J22: Energy Field Services | K22: Corbalan Federico Martin | L22: EFR-FN0941 | N22: Ulla Milagros | O22: =VLOOKUP(L22,CECOs!A:B,2,0) -> Indirectos PRR | P22: =VLOOKUP(B:B,CECOs!G:I,3,FALSE) -> Personalnooperativo | Q22: =IF(_xlfn.XLOOKUP(L22,CECOs!A:A,CECOs!C:C,"")="",K22,_xlfn.XLOOKUP(L22,CECOs!A:A,CECOs!C:C,"")) -> Corbalan Federico Martin | R22: EFIS | S22: NQN | U22: Human Resources | V22: WC | AB22: Headcount | AD22: SI
A23: 46266 | B23: 3437846 | C23: Labor Relations Expert | D23: EFIS | E23: EFIS | G23: =Table1[[#This Row],[DESCRIPCION_POSICION]] -> Labor Relations Expert | I23: AR-NEUQUÉN | J23: Energy Field Services | K23: Gaisch Alejandro Hector | L23: EFR-FN0941 | N23: Vacante RL Sep/26 | O23: =VLOOKUP(L23,CECOs!A:B,2,0) -> Indirectos PRR | P23: =VLOOKUP(B:B,CECOs!G:I,3,FALSE) -> Personalnooperativo | Q23: =IF(_xlfn.XLOOKUP(L23,CECOs!A:A,CECOs!C:C,"")="",K23,_xlfn.XLOOKUP(L23,CECOs!A:A,CECOs!C:C,"")) -> Gaisch Alejandro Hector | R23: EFIS | S23: NQN | U23: Labor Relations & CORE | V23: WC | AB23: Headcount | AD23: SI
A24: 46266 | B24: 3392813 | C24: Labor Relations Expert | D24: EFIS | E24: EFIS | G24: =Table1[[#This Row],[DESCRIPCION_POSICION]] -> Labor Relations Expert | H24: DU30264777 | I24: AR-NEUQUÉN | J24: Energy Field Services | K24: Gaisch Alejandro Hector | L24: EFR-FN0941 | N24: Seguel Maria Fernanda | O24: =VLOOKUP(L24,CECOs!A:B,2,0) -> Indirectos PRR | P24: =VLOOKUP(B:B,CECOs!G:I,3,FALSE) -> Personalnooperativo | Q24: =IF(_xlfn.XLOOKUP(L24,CECOs!A:A,CECOs!C:C,"")="",K24,_xlfn.XLOOKUP(L24,CECOs!A:A,CECOs!C:C,"")) -> Gaisch Alejandro Hector | R24: EFIS | S24: NQN | T24: 1010254 | U24: Labor Relations & CORE | V24: WC | AB24: Headcount | AD24: SI
A25: 46266 | B25: 3392814 | C25: Quality Analyst | D25: EFIS | E25: EFIS | G25: =Table1[[#This Row],[DESCRIPCION_POSICION]] -> Quality Analyst | H25: DU36010010 | I25: AR-NEUQUÉN | J25: Energy Field Services | K25: Seri Walter Omar | L25: EFR-FN0941 | N25: Campora Camila María | O25: =VLOOKUP(L25,CECOs!A:B,2,0) -> Indirectos PRR | P25: =VLOOKUP(B:B,CECOs!G:I,3,FALSE) -> Personalnooperativo | Q25: =IF(_xlfn.XLOOKUP(L25,CECOs!A:A,CECOs!C:C,"")="",K25,_xlfn.XLOOKUP(L25,CECOs!A:A,CECOs!C:C,"")) -> Seri Walter Omar | R25: EFIS | S25: NQN | T25: 1013992 | U25: Quality | V25: WC | AB25: Headcount | AD25: SI
A26: 46266 | B26: 3392815 | C26: General Services Supervisor | D26: EFIS | E26: EFIS | G26: =Table1[[#This Row],[DESCRIPCION_POSICION]] -> General Services Supervisor | H26: DU33067280 | I26: AR-NEUQUÉN | J26: Energy Field Services | K26: Zuluaga Gabriel | L26: EFR-FN0941 | N26: Rizzo Sebastian | O26: =VLOOKUP(L26,CECOs!A:B,2,0) -> Indirectos PRR | P26: =VLOOKUP(B:B,CECOs!G:I,3,FALSE) -> Supervisoroperativo/Producción | Q26: =IF(_xlfn.XLOOKUP(L26,CECOs!A:A,CECOs!C:C,"")="",K26,_xlfn.XLOOKUP(L26,CECOs!A:A,CECOs!C:C,"")) -> Zuluaga Gabriel | R26: EFIS | S26: NQN | T26: 1005464 | U26: General Services | V26: WC | AB26: Headcount | AD26: SI
A27: 46266 | B27: 3392816 | C27: HSE Sr. Supervisor | D27: EFIS | E27: EFIS | G27: =Table1[[#This Row],[DESCRIPCION_POSICION]] -> HSE Sr. Supervisor | H27: DU36669185 | I27: AR-NEUQUÉN | J27: Energy Field Services | K27: Chazarreta Jose Antonio | L27: EFR-FN0945 | N27: Figueroa Franco Martin | O27: =VLOOKUP(L27,CECOs!A:B,2,0) -> SAS PRR | P27: =VLOOKUP(B:B,CECOs!G:I,3,FALSE) -> SupervisoresSAS/OT | Q27: =IF(_xlfn.XLOOKUP(L27,CECOs!A:A,CECOs!C:C,"")="",K27,_xlfn.XLOOKUP(L27,CECOs!A:A,CECOs!C:C,"")) -> Chazarreta Jose Antonio | R27: EFIS | S27: NQN | T27: 1005233 | U27: Health & Safety | V27: WC | AB27: Headcount | AD27: SI
A28: 46266 | B28: 3392817 | C28: HSE Sr. Supervisor | D28: EFIS | E28: EFIS | G28: =Table1[[#This Row],[DESCRIPCION_POSICION]] -> HSE Sr. Supervisor | H28: DU33926407 | I28: AR-NEUQUÉN | J28: Energy Field Services | K28: Chazarreta Jose Antonio | L28: EFR-FN0945 | N28: Mora Federico | O28: =VLOOKUP(L28,CECOs!A:B,2,0) -> SAS PRR | P28: =VLOOKUP(B:B,CECOs!G:I,3,FALSE) -> SupervisoresSAS/OT | Q28: =IF(_xlfn.XLOOKUP(L28,CECOs!A:A,CECOs!C:C,"")="",K28,_xlfn.XLOOKUP(L28,CECOs!A:A,CECOs!C:C,"")) -> Chazarreta Jose Antonio | R28: EFIS | S28: NQN | T28: 1005233 | U28: Health & Safety | V28: WC | AB28: Headcount | AD28: SI
A29: 46266 | B29: 3392818 | C29: HSE Sr. Supervisor | D29: EFIS | E29: EFIS | G29: =Table1[[#This Row],[DESCRIPCION_POSICION]] -> HSE Sr. Supervisor | H29: DU28387841 | I29: AR-NEUQUÉN | J29: Energy Field Services | K29: Chazarreta Jose Antonio | L29: EFR-FN0945 | N29: Sea Oscar Ariel | O29: =VLOOKUP(L29,CECOs!A:B,2,0) -> SAS PRR | P29: =VLOOKUP(B:B,CECOs!G:I,3,FALSE) -> SupervisoresSAS/OT | Q29: =IF(_xlfn.XLOOKUP(L29,CECOs!A:A,CECOs!C:C,"")="",K29,_xlfn.XLOOKUP(L29,CECOs!A:A,CECOs!C:C,"")) -> Chazarreta Jose Antonio | R29: EFIS | S29: NQN | T29: 1005233 | U29: Health & Safety | V29: WC | AB29: Headcount | AD29: SI
A30: 46266 | B30: 3392819 | C30: HSE Sr. Supervisor | D30: EFIS | E30: EFIS | G30: =Table1[[#This Row],[DESCRIPCION_POSICION]] -> HSE Sr. Supervisor | H30: DU33885206 | I30: AR-NEUQUÉN | J30: Energy Field Services | K30: Chazarreta Jose Antonio | L30: EFR-FN0945 | N30: Palma Belen del Milagro | O30: =VLOOKUP(L30,CECOs!A:B,2,0) -> SAS PRR | P30: =VLOOKUP(B:B,CECOs!G:I,3,FALSE) -> SupervisoresSAS/OT | Q30: =IF(_xlfn.XLOOKUP(L30,CECOs!A:A,CECOs!C:C,"")="",K30,_xlfn.XLOOKUP(L30,CECOs!A:A,CECOs!C:C,"")) -> Chazarreta Jose Antonio | R30: EFIS | S30: NQN | T30: 1005233 | U30: Health & Safety | V30: WC | AB30: Headcount | AD30: SI
A31: 46266 | B31: 3392820 | C31: HSE Sr. Supervisor | D31: EFIS | E31: EFIS | G31: =Table1[[#This Row],[DESCRIPCION_POSICION]] -> HSE Sr. Supervisor | H31: DU23918152 | I31: AR-NEUQUÉN | J31: Energy Field Services | K31: Lemes Mariana De Los Angeles | L31: EFR-FN0945 | N31: Huaiquiñir Juan Jose | O31: =VLOOKUP(L31,CECOs!A:B,2,0) -> SAS PRR | P31: =VLOOKUP(B:B,CECOs!G:I,3,FALSE) -> SupervisoresSAS/OT | Q31: =IF(_xlfn.XLOOKUP(L31,CECOs!A:A,CECOs!C:C,"")="",K31,_xlfn.XLOOKUP(L31,CECOs!A:A,CECOs!C:C,"")) -> Lemes Mariana De Los Angeles | R31: EFIS | S31: NQN | T31: 1005233 | U31: Health & Safety | V31: WC | AB31: Headcount | AD31: SI
A32: 46266 | B32: 3392821 | C32: HSE Sr. Supervisor | D32: EFIS | E32: EFIS | G32: =Table1[[#This Row],[DESCRIPCION_POSICION]] -> HSE Sr. Supervisor | H32: DU28254170 | I32: AR-NEUQUÉN | J32: Energy Field Services | K32: Lemes Mariana De Los Angeles | L32: EFR-FN0945 | N32: Galdame Carlos David | O32: =VLOOKUP(L32,CECOs!A:B,2,0) -> SAS PRR | P32: =VLOOKUP(B:B,CECOs!G:I,3,FALSE) -> SupervisoresSAS/OT | Q32: =IF(_xlfn.XLOOKUP(L32,CECOs!A:A,CECOs!C:C,"")="",K32,_xlfn.XLOOKUP(L32,CECOs!A:A,CECOs!C:C,"")) -> Lemes Mariana De Los Angeles | R32: EFIS | S32: NQN | T32: 1005233 | U32: Health & Safety | V32: WC | AB32: Headcount | AD32: SI
A33: 46266 | B33: 3424838 | C33: Operations Services Coordinator | D33: EFIS | E33: EFIS | G33: =Table1[[#This Row],[DESCRIPCION_POSICION]] -> Operations Services Coordinator | H33: DU24260286 | I33: AR-NEUQUÉN | J33: Energy Field Services | K33: Lopez Rodrigo Gaston | L33: EFR-2E0970 | N33: Mercado Mauricio Edgardo | O33: =VLOOKUP(L33,CECOs!A:B,2,0) -> Facilitadores LT2E | P33: =VLOOKUP(B:B,CECOs!G:I,3,FALSE) -> FacilitadordeServicios | Q33: =IF(_xlfn.XLOOKUP(L33,CECOs!A:A,CECOs!C:C,"")="",K33,_xlfn.XLOOKUP(L33,CECOs!A:A,CECOs!C:C,"")) -> Lopez Rodrigo Gaston | R33: EFIS | S33: NQN | U33: O&M Services | V33: WC | AB33: Headcount | AD33: SI
A34: 46266 | B34: 3424839 | C34: Operations Services Coordinator | D34: EFIS | E34: EFIS | G34: =Table1[[#This Row],[DESCRIPCION_POSICION]] -> Operations Services Coordinator | H34: DU27841592 | I34: AR-NEUQUÉN | J34: Energy Field Services | K34: Lopez Rodrigo Gaston | L34: EFR-2E0970 | N34: Fredes Ruben Oscar | O34: =VLOOKUP(L34,CECOs!A:B,2,0) -> Facilitadores LT2E | P34: =VLOOKUP(B:B,CECOs!G:I,3,FALSE) -> FacilitadordeServicios | Q34: =IF(_xlfn.XLOOKUP(L34,CECOs!A:A,CECOs!C:C,"")="",K34,_xlfn.XLOOKUP(L34,CECOs!A:A,CECOs!C:C,"")) -> Lopez Rodrigo Gaston | R34: EFIS | S34: NQN | U34: O&M Services | V34: WC | AB34: Headcount | AD34: SI
A35: 46266 | B35: 3395761 | C35: Medical Assistant | D35: EFIS | E35: EFIS | G35: =Table1[[#This Row],[DESCRIPCION_POSICION]] -> Medical Assistant | H35: DU33135662 | I35: AR-NEUQUÉN | J35: Energy Field Services | K35: Martel Maximiliano Jose Tomas | L35: EFR-FN0945 | N35: Feruglio Adrian Federico | O35: =VLOOKUP(L35,CECOs!A:B,2,0) -> SAS PRR | P35: =VLOOKUP(B:B,CECOs!G:I,3,FALSE) -> Personalnooperativo | Q35: =IF(_xlfn.XLOOKUP(L35,CECOs!A:A,CECOs!C:C,"")="",K35,_xlfn.XLOOKUP(L35,CECOs!A:A,CECOs!C:C,"")) -> Martel Maximiliano Jose Tomas | R35: EFIS | S35: NQN | T35: 1005233 | U35: Health & Safety | V35: WC | AB35: Headcount | AD35: SI
A36: 46266 | B36: 3395760 | C36: Medical Assistant | D36: EFIS | E36: EFIS | G36: =Table1[[#This Row],[DESCRIPCION_POSICION]] -> Medical Assistant | H36: DU26638146 | I36: AR-NEUQUÉN | J36: Energy Field Services | K36: Martel Maximiliano Jose Tomas | L36: EFR-FN0945 | N36: Schlosser Adolfo Julio | O36: =VLOOKUP(L36,CECOs!A:B,2,0) -> SAS PRR | P36: =VLOOKUP(B:B,CECOs!G:I,3,FALSE) -> Personalnooperativo | Q36: =IF(_xlfn.XLOOKUP(L36,CECOs!A:A,CECOs!C:C,"")="",K36,_xlfn.XLOOKUP(L36,CECOs!A:A,CECOs!C:C,"")) -> Martel Maximiliano Jose Tomas | R36: EFIS | S36: NQN | T36: 1005233 | U36: Health & Safety | V36: WC | AB36: Headcount | AD36: SI
A37: 46266 | B37: 3392823 | C37: Environmental Supervisor | D37: EFIS | E37: EFIS | G37: =Table1[[#This Row],[DESCRIPCION_POSICION]] -> Environmental Supervisor | H37: DU33316128 | I37: AR-NEUQUÉN | J37: Energy Field Services | K37: Carreño Venegas Cecilia | L37: EFR-FN0945 | N37: Leiva Ricardo Alejandro | O37: =VLOOKUP(L37,CECOs!A:B,2,0) -> SAS PRR | P37: =VLOOKUP(B:B,CECOs!G:I,3,FALSE) -> SupervisoresSAS/OT | Q37: =IF(_xlfn.XLOOKUP(L37,CECOs!A:A,CECOs!C:C,"")="",K37,_xlfn.XLOOKUP(L37,CECOs!A:A,CECOs!C:C,"")) -> Carreño Venegas Cecilia | R37: EFIS | S37: NQN | T37: 1010264 | U37: Environmental | V37: WC | AB37: Headcount | AD37: SI
A38: 46266 | B38: 3414072 | C38: Environmental Sr. Supervisor | D38: EFIS | E38: EFIS | G38: =Table1[[#This Row],[DESCRIPCION_POSICION]] -> Environmental Sr. Supervisor | H38: DU36344221 | I38: AR-NEUQUÉN | J38: Energy Field Services | K38: Carreño Venegas Cecilia | L38: EFR-FN0945 | N38: Acuña Fernanda Natali | O38: =VLOOKUP(L38,CECOs!A:B,2,0) -> SAS PRR | P38: =VLOOKUP(B:B,CECOs!G:I,3,FALSE) -> SupervisoresSAS/OT | Q38: =IF(_xlfn.XLOOKUP(L38,CECOs!A:A,CECOs!C:C,"")="",K38,_xlfn.XLOOKUP(L38,CECOs!A:A,CECOs!C:C,"")) -> Carreño Venegas Cecilia | R38: EFIS | S38: NQN | U38: Environmental | V38: WC | AB38: Headcount | AD38: SI
A39: 46266 | B39: 3392824 | C39: Health Auxiliar | D39: EFIS | E39: EFIS | G39: =Table1[[#This Row],[DESCRIPCION_POSICION]] -> Health Auxiliar | H39: DU29463906 | I39: AR-NEUQUÉN | J39: Energy Field Services | K39: Martel Maximiliano Jose Tomas | L39: EFR-FN0945 | N39: Prieto Beatriz Alejandra | O39: =VLOOKUP(L39,CECOs!A:B,2,0) -> SAS PRR | P39: =VLOOKUP(B:B,CECOs!G:I,3,FALSE) -> Personalnooperativo | Q39: =IF(_xlfn.XLOOKUP(L39,CECOs!A:A,CECOs!C:C,"")="",K39,_xlfn.XLOOKUP(L39,CECOs!A:A,CECOs!C:C,"")) -> Martel Maximiliano Jose Tomas | R39: EFIS | S39: NQN | T39: 1005233 | U39: Health & Safety | V39: WC | AB39: Headcount | AD39: SI
A40: 46266 | B40: 3392825 | C40: Operations Technology Maint. Engineer | D40: EFIS | E40: EFIS | G40: =Table1[[#This Row],[DESCRIPCION_POSICION]] -> Operations Technology Maint. Engineer | H40: DU33993061 | I40: AR-NEUQUÉN | J40: Energy Field Services | K40: Contreras Fernando Andres | L40: EFR-FN0930 | N40: Crespillo Faur Adrian Alejandro | O40: =VLOOKUP(L40,CECOs!A:B,2,0) -> OT PRR | P40: =VLOOKUP(B:B,CECOs!G:I,3,FALSE) -> SupervisoresSAS/OT | Q40: =IF(_xlfn.XLOOKUP(L40,CECOs!A:A,CECOs!C:C,"")="",K40,_xlfn.XLOOKUP(L40,CECOs!A:A,CECOs!C:C,"")) -> Contreras Fernando Andres | R40: EFIS | S40: NQN | T40: 1010274 | U40: Maintenance | V40: WC | AB40: Headcount | AD40: SI
...

Sheet REFERENCIAS 
A1: REFERENCIAS COLORES
A2: VACANTES
A3: MOVIMIENTOS
A4: INGRESOS

Sheet CECOs
A1: Ceco EFIS Específico | B1: Órden EFIS | C1: Facilitador | G1: S | H1: Descripción Posición | I1: Clasificación
A2: EFF-FP0901 | B2: Oper campo FP | C2: HUARTE, ESTEBAN | G2: 3392801 | H2: PRR Facilitadores FORT | I2: FacilitadordeServicios
A3: EFF-FP0902 | B3: Oper Well Services FP | C3: MACIAS, OSCAR / SAFFE, JULIAN | G3: 3392802 | H3: PRR Facilitadores FORT | I3: FacilitadordeServicios
A4: EFF-FP0903 | B4: Almacenamiento de Agua FP | C4: HUARTE, ESTEBAN | G4: 3392803 | H4: PRR Facilitadores FORT | I4: FacilitadordeServicios
A5: EFF-FP0905 | B5: Oper. LTS FP | C5: HUARTE, ESTEBAN | G5: 3392804 | H5: Facilitador Well Services - FP | I5: FacilitadordeServicios
A6: EFF-FP0906 | B6: Oper. EPF FP | C6: HUARTE, ESTEBAN | G6: 3392805 | H6: PRR Facilitadores CONV - Facilitador LBAS | I6: FacilitadordeServicios
A7: EFF-FP0911 | B7: Operadores SALA EPF | G7: 3392806 | H7: PRR Facilitadores FORT | I7: FacilitadordeServicios
A8: EFF-FP0907 | B8: Oper. Planta Compresión FP | C8: HUARTE, ESTEBAN | G8: 3392808 | H8: PRR Facilitadores FORT | I8: FacilitadordeServicios
A9: EFF-FP0908 | B9: Oper. PTA FP | C9: HUARTE, ESTEBAN | G9: 3392811 | H9: Indirectos PRR - RRHH | I9: Personalnooperativo
A10: EFF-FP0909 | B10: Tareas Generales Planta FP | C10: HUARTE, ESTEBAN | G10: 3392812 | H10: Indirectos PRR - RRHH | I10: Personalnooperativo
A11: EFF-FP0921 | B11: Mtto Mecánico FP | C11: CORDOVA, DANIELA / ALTAMIRANDA, LEANDRO | G11: 3392813 | H11: Indirectos PRR - RRLL | I11: Personalnooperativo
A12: EFF-FP0922 | B12: Mtto Eléctrico FP | C12: CORDOVA, DANIELA / ALTAMIRANDA, LEANDRO | G12: 3392814 | H12: Indirectos PRR - Calidad | I12: Personalnooperativo
A13: EFF-FP0923 | B13: Mtto Instrumentos FP | C13: CORDOVA, DANIELA / ALTAMIRANDA, LEANDRO | G13: 3392815 | H13: Indirectos PRR - SERGE Sup. Flota | I13: Supervisoroperativo/Producción
A14: EFF-FP0924 | B14: Compresión FP | C14: CORDOVA, DANIELA / ALTAMIRANDA, LEANDRO | G14: 3392816 | H14: SAS PRR | I14: SupervisoresSAS/OT
A15: EFF-FP0925 | B15: Soldadura FP | C15: CORDOVA, DANIELA / ALTAMIRANDA, LEANDRO | G15: 3392817 | H15: SAS PRR | I15: SupervisoresSAS/OT
A16: EFF-FP0926 | B16: Tareas Generales Mtto FP | C16: CORDOVA, DANIELA / ALTAMIRANDA, LEANDRO | G16: 3392818 | H16: SAS PRR | I16: SupervisoresSAS/OT
A17: EFF-FP0927 | B17: Asistencia a Planta FP | C17: CORDOVA, DANIELA / ALTAMIRANDA, LEANDRO | G17: 3392819 | H17: SAS PRR | I17: SupervisoresSAS/OT
A18: EFF-FP0928 | B18: Engrase FP | C18: CORDOVA, DANIELA / ALTAMIRANDA, LEANDRO | G18: 3392820 | H18: SAS PRR | I18: SupervisoresSAS/OT
A19: EFF-FP0929 | B19: T. Grales Serge Fp | C19: CASAL, GUSTAVO | G19: 3392821 | H19: SAS PRR | I19: SupervisoresSAS/OT
A20: EFF-2E0929 | B20: T. Grales Serge LT2E | C20: MERCADO, MAURICIO / FREDES, RUBEN | G20: 3392822 | H20: SAS PRR | I20: SupervisoresSAS/OT
A21: EFF-FP0930 | B21: OT FP | G21: 3395760 | H21: SAS PRR | I21: Personalnooperativo
A22: EFF-FP0931 | B22: Integridad FP | G22: 3395761 | H22: SAS PRR | I22: Personalnooperativo
A23: EFF-FP0932 | B23: Programador FP | G23: 3392823 | H23: SAS PRR | I23: SupervisoresSAS/OT
A24: EFF-FP0942 | B24: Aux. Almacén FP | C24: CASAL, GUSTAVO | G24: 3392824 | H24: SAS PRR | I24: Personalnooperativo
A25: EFF-2E0942 | B25: Aux. Almacén LT2E | C25: MERCADO, MAURICIO / FREDES, RUBEN | G25: 3392825 | H25: Mantenimiento - OT PRR - PRR FORT | I25: SupervisoresSAS/OT
A26: EFF-FP0943 | B26: Chofer FP | C26: CASAL, GUSTAVO | G26: 3392826 | H26: Mantenimiento - OT PRR - PRR FORT | I26: SupervisoresSAS/OT
A27: EFF-FP0944 | B27: Mecánicos FP | C27: CASAL, GUSTAVO | G27: 3392827 | H27: Mantenimiento - OT PRR - PRR FORT | I27: SupervisoresSAS/OT
A28: EFF-FP0945 | B28: SAS FP | G28: 3392828 | H28: Mantenimiento - OT PRR - PRR FORT | I28: SupervisoresSAS/OT
A29: EFF-LB0901 | B29: Oper campo LBAS | C29: BECHARA, LUCAS ANTONIO | G29: 3392829 | H29: Mantenimiento - OT PRR - PRR FORT | I29: SupervisoresSAS/OT
A30: EFF-LB0904 | B30: Tareas Generales Prod LBAS | C30: BECHARA, LUCAS ANTONIO | G30: 3392830 | H30: Mantenimiento - OT PRR - PRR FORT | I30: SupervisoresSAS/OT
A31: EFF-LB0908 | B31: Oper. PTA LBAS | C31: BECHARA, LUCAS ANTONIO | G31: 3392831 | H31: Mantenimiento - OT PRR - PRR LBAS/ASAL | I31: SupervisoresSAS/OT
A32: EFF-LB0921 | B32: Mtto Mecánico LBAS | C32: BECHARA, LUCAS ANTONIO | G32: 3392834 | H32: PRR Supervisores Mtto FP | I32: Supervisoroperativo/Producción
A33: EFF-LB0922 | B33: Mtto Eléctrico LBAS | C33: BECHARA, LUCAS ANTONIO | G33: 3392835 | H33: PRR Supervisores Mtto FP | I33: Supervisoroperativo/Producción
A34: EFF-LB0923 | B34: Mtto Instrumentos LBAS | C34: BECHARA, LUCAS ANTONIO | G34: 3401242 | H34: PRR Supervisores Mtto FP | I34: Supervisoroperativo/Producción
A35: EFF-LB0925 | B35: Soldadura LBAS | C35: BECHARA, LUCAS ANTONIO | G35: 3401243 | H35: PRR Supervisores Mtto FP | I35: Supervisoroperativo/Producción
A36: EFF-LB0929 | B36: T. Grales Serge LBAS | G36: 3395519 | H36: Producción - PRR Supervisores Producción - PRR - Sup. Producción LT1N | I36: Supervisoroperativo/Producción
A37: EFF-LB0930 | B37: OT LBAS | G37: 3395768 | H37: Producción - PRR Supervisores Producción - PRR - Sup. Producción LT1N | I37: Supervisoroperativo/Producción
A38: EFF-LB0931 | B38: Integridad LBAS | G38: 3392840 | H38: Mantenimiento - Integridad PRR - PRR FP | I38: Supervisoroperativo/Producción
A39: EFF-LB0932 | B39: Programador LBAS | G39: 3392841 | H39: Mantenimiento - Programador PRR - PRR FP | I39: Personalnooperativo
A40: EFF-LB0942 | B40: Aux. Almacén LBAS | C40: BECHARA, LUCAS ANTONIO | G40: 3392842 | H40: Mantenimiento - Programador PRR - PRR FP | I40: Personalnooperativo
...

Sheet Sheet1
A3: Etiquetas de fila | B3: Count of DESCRIPCION_PERSONA
A4: Bechara Lucas Antonio | B4: 76
A5: Aux. Almacén LBAS | B5: 1
A6: Aux. Almacén SALA | B6: 1
A7: Mtto Eléctrico LBAS | B7: 2
A8: Mtto Eléctrico SALA | B8: 3
A9: Mtto Instrumentos LBAS | B9: 2
A10: Mtto Instrumentos SALA | B10: 2
A11: Mtto Mecánico LBAS | B11: 3
A12: Mtto Mecánico SALA | B12: 2
A13: Oper campo LBAS | B13: 11
A14: Oper campo SALA | B14: 17
A15: Oper. PTA LBAS | B15: 13
... A55: Total general | B55: 256

Sheet Qs
A1: WC_BC | B1: (Todas)
A3: Count of PERSONA | B3: Etiquetas de columna
A4: Etiquetas de fila | B4: SI | C4: RELEVO VACACIONES | D4: PF 3 meses | E4: Total general
A5: EFF-FP0901 | B5: 18 | E5: 18
A6: Abarzua Mario Hernan | B6: 1 | E6: 1
A7: Astorga Sergio Edgardo | B7: 1 | E7: 1
A8: Bunajul Emiliano Miguel | B8: 1 | E8: 1
A9: Castro Marcos Aurelio | B9: 1 | E9: 1
A10: Donnini Julio Samuel | B10: 1 | E10: 1
A11: Fonseca Lucas Ivan | B11: 1 | E11: 1
A12: Fuentes Roberto Alejandro | B12: 1 | E12: 1
A13: Garce Mauro Xavier | B13: 1 | E13: 1
A14: Gonzalez Perez Andy Paolo | B14: 1 | E14: 1
A15: Gutierrez Oscar Javier | B15: 1 | E15: 1
A16: Hernandez Ramon Horacio | B16: 1 | E16: 1
... A31: Fuentes Lopez Gaston Emiliano | B31: 1 | E31: 1
A32: Kochereschuk Brian Alexis
A33: Lopez Ramiro Alejandro Antonio
A34: Garcia Leandro Erik Maximiliano
A35: Prieto Hugo Ernesto
A36: Silva Diego Mauro
A37: Alderete Pablo
A38: Matus Mondaca Gustavo Adan
A39: Firpo Gabriel Cesar Ivan
A40: Canales Ruiz Axel Agustín
A41: Jesus Carlos Abraham
A42: Diaz Jonatan Nicolas
A43: Rosas Diego Nicolas
A44: Cardenas Cristian Ivan
A45: EFF-FP0903 | B45: 5 | E45: 5
A46: Candia Matias Emanuel | B46: 1 | E46: 1
A47: Gallas Fernando Ezequiel | B47: 1 | E47: 1
A48: Gonzalez Jorge Omar | B48: 1 | E48: 1
A49: Pineda Jorge Oscar | B49: 1 | E49: 1
A50: Sandoval Marcos Alexis Aryon | B50: 1 | E50: 1
A51: EFF-FP0905 | B51: 10 | E51: 10
A52: Cordoba Diego Gerardo | B52: 1 | E52: 1
A53: Estelrrig Miguel Horacio | B53: 1 | E53: 1
A54: Figueroa Pablo Emanuel | B54: 1 | E54: 1
A55: Huenchullan Jose Enrique | B55: 1 | E55: 1
...

Sheet Mes
A1: {=CELL("filename",A1)} -> #VALUE!
A2: =DATE( RIGHT(MID(MID(A1,FIND("[",A1)+1,FIND("]",A1)-FIND("[",A1)-1),SEARCH(".xl",MID(A1,FIND("[",A1)+1,FIND("]",A1)-FIND("[",A1)-1))-7,7),4), LEFT(MID(MID(A1,FIND("[",A1)+1,FIND("]",A1)-FIND("[",A1)-1),SEARCH(".xl",MID(A1,FIND("[",A1)+1,FIND("]",A1)-FIND("[",A1)-1))-7,7),2), 1 ) -> #VALUE!

Sheet SOLAPAMIENTO
B1: POS | C1: Apellido | D1: Nombre | E1: CECO | F1: DNI | G1: COMENTARIOS
A2: 45798 | B2: 3392969 | G2: revisar si es una pos real/vacante?
A3: 45798 | B3: 3393023 | C3: De la Fuente | G3: revisar si es una pos real/vacante?
G4: ELIMINADA EN JULIO (POR CAMBIOS DE CONV Y ROTACIÓN DE CANCINO A LBAS)
A9: # | B9: ID Posición | C9: Posición | D9: CECO | E9: Dirección | F9: Agrupador Gerencia | G9: Gerencia Jefatura | H9: Operación | I9: Jefe
A10: 1 | B10: 3392814 | C10: Vacante - Quality Analyst | D10: EFR-FN0941 | E10: Operations & Argentina Conventional | F10: Quality | G10: Quality | H10: Neuquén - EFiS | I10: Seri Walter Omar | J10: =VLOOKUP(B10,#REF!,13,0) -> #REF!
A11: 1 | B11: 3393032 | C11: Vacante - Oficial de Oficios | D11: EFF-FP0921 | E11: Cuenca Neuquina & Vaca Muerta | F11: Operations & Engineering | G11: Mantainance Services | H11: Neuquén - EFiS | I11: Lemos Sergio Dario | J11: =VLOOKUP(B11,#REF!,13,0) -> #REF!
A12: 1 | B12: 3392884 | C12: Vacante - Oficial Sr. de Oficios | D12: EFF-LB0925 | E12: Cuenca Neuquina & Vaca Muerta | F12: Operations & Engineering | G12: Mantainance Services | H12: Neuquén - EFiS | I12: Altamiranda Leandro Damian | J12: =VLOOKUP(B12,#REF!,13,0) -> #REF!
A13: 1 | B13: 3393037 | C13: Vacante - Operador Principal de Cuadrilla | D13: EFF-FP0925 | E13: Cuenca Neuquina & Vaca Muerta | F13: Operations & Engineering | G13: Mantainance Services | H13: Neuquén - EFiS | I13: Lemos Sergio Dario | J13: =VLOOKUP(B13,#REF!,13,0) -> #REF!
A14: 1 | B14: 3392953 | C14: Licencia - Carrasco | D14: EFF-FP0908 | E14: Cuenca Neuquina & Vaca Muerta | F14: Operations & Engineering | G14: Operations Services | H14: Neuquén - EFiS | I14: Bechara Lucas Antonio | J14: =VLOOKUP(B14,#REF!,13,0) -> #REF!
A15: 1 | B15: 3392948 | C15: Licencia - Nicloux | D15: EFF-FP0908 | E15: Cuenca Neuquina & Vaca Muerta | F15: Operations & Engineering | G15: Operations Services | H15: Neuquén - EFiS | I15: Bechara Lucas Antonio | J15: =VLOOKUP(B15,#REF!,13,0) -> #REF!
A16: 1 | B16: 3392986 | C16: Vacante - Recorredor Especializado | D16: EFF-FP0901 | E16: Cuenca Neuquina & Vaca Muerta | F16: Operations & Engineering | G16: Operations Services | H16: Neuquén - EFiS | I16: Macias Ceferino Oscar | J16: =VLOOKUP(B16,#REF!,13,0) -> #REF!
A17: 1 | B17: 3392846 | C17: Vacante - Integrity Supervisor | D17: EFR-FN0931 | E17: Cuenca Neuquina & Vaca Muerta | F17: Operations & Engineering | G17: Maintenance | H17: Neuquén - EFiS | I17: Diaz Luis Alberto | J17: =VLOOKUP(B17,#REF!,13,0) -> #REF!
A18: 1 | B18: 3401242 | C18: Vacante - Maintenance Sr. Supervisor | D18: EFR-FN0900 | E18: Cuenca Neuquina & Vaca Muerta | F18: Operations & Engineering | G18: Maintenance | H18: Neuquén - EFiS | I18: Mazoue Juan Manuel | J18: =VLOOKUP(B18,#REF!,13,0) -> #REF!
